Workbook

Sheet years_sum1_DM
A1: X | B1: date | C1: meanRECO | D1: year | E1: max_pulse_duration
A2: 1 | B2: 41274 | C2: 0.039035644 | D2: 2012 | E2: 0
A3: 2 | B3: 41275 | C3: 0.092394151 | D3: 2013 | E3: 0
A4: 3 | B4: 41276 | C4: 0.14453692 | D4: 2013 | E4: 0
A5: 4 | B5: 41277 | C5: 0.13412339 | D5: 2013 | E5: 0
A6: 5 | B6: 41278 | C6: 0.10699103 | D6: 2013 | E6: 0
A7: 6 | B7: 41279 | C7: 0.15234982 | D7: 2013 | E7: 0
A8: 7 | B8: 41280 | C8: 0.34674145 | D8: 2013 | E8: 0
A9: 8 | B9: 41281 | C9: 0.24077825 | D9: 2013 | E9: 0
A10: 9 | B10: 41282 | C10: 0.31749283 | D10: 2013 | E10: 0
A11: 10 | B11: 41283 | C11: 0.45287389 | D11: 2013 | E11: 0
A12: 11 | B12: 41284 | C12: 0.51621977 | D12: 2013 | E12: 0
A13: 12 | B13: 41285 | C13: 0.31304548 | D13: 2013 | E13: 0
... A365: 366 | B365: 41639 | C365: 0.11498517 | D365: 2013 | E365: 0

Sheet 13
A1: X | B1: date | C1: meanRECO | D1: year | E1: max_pulse_duration
A2: 1 | B2: 41274 | C2: 0.039035644 | D2: 2012 | E2: 0
A3: 2 | B3: 41275 | C3: 0.092394151 | D3: 2013 | E3: 0
A4: 3 | B4: 41276 | C4: 0.14453692 | D4: 2013 | E4: 0
A5: 4 | B5: 41277 | C5: 0.13412339 | D5: 2013 | E5: 0
A6: 5 | B6: 41278 | C6: 0.10699103 | D6: 2013 | E6: 0
A7: 6 | B7: 41279 | C7: 0.15234982 | D7: 2013 | E7: 0
A8: 7 | B8: 41280 | C8: 0.34674145 | D8: 2013 | E8: 0
A9: 8 | B9: 41281 | C9: 0.24077825 | D9: 2013 | E9: 0
A10: 9 | B10: 41282 | C10: 0.31749283 | D10: 2013 | E10: 0
A11: 10 | B11: 41283 | C11: 0.45287389 | D11: 2013 | E11: 0
A12: 11 | B12: 41284 | C12: 0.51621977 | D12: 2013 | E12: 0
A13: 12 | B13: 41285 | C13: 0.31304548 | D13: 2013 | E13: 0
... A365: 366 | B365: 41639 | C365: 0.11498517 | D365: 2013 | E365: 0

Sheet Лист24
A1: X | B1: date | D1: meanRECO | E1: year | F1: max_pulse_duration
A2: 1 | B2: 41274 | D2: 0.039035644 | E2: 2012 | F2: 0 | I2: 0.039035644
A3: 2 | B3: 41275 | C3: =B3-B2 -> 1 | D3: 0.092394151 | E3: 2013 | F3: 0 | I3: =D3*C3 -> 0.092394151 | J3: =I3+I2 -> 0.13142979
A4: 3 | B4: 41276 | C4: =B4-B3 -> 1 | D4: 0.14453692 | E4: 2013 | F4: 0 | I4: =D4*C4 -> 0.14453692 | J4: =I4+J3 -> 0.27596671
A5: 4 | B5: 41277 | C5: =B5-B4 -> 1 | D5: 0.13412339 | E5: 2013 | F5: 0 | I5: =D5*C5 -> 0.13412339 | J5: =I5+J4 -> 0.4100901
A6: 5 | B6: 41278 | C6: =B6-B5 -> 1 | D6: 0.10699103 | E6: 2013 | F6: 0 | I6: =D6*C6 -> 0.10699103 | J6: =I6+J5 -> 0.51708113
A7: 6 | B7: 41279 | C7: =B7-B6 -> 1 | D7: 0.15234982 | E7: 2013 | F7: 0 | I7: =D7*C7 -> 0.15234982 | J7: =I7+J6 -> 0.66943095
A8: 7 | B8: 41280 | C8: =B8-B7 -> 1 | D8: 0.34674145 | E8: 2013 | F8: 0 | I8: =D8*C8 -> 0.34674145 | J8: =I8+J7 -> 1.0161724
A9: 8 | B9: 41281 | C9: =B9-B8 -> 1 | D9: 0.24077825 | E9: 2013 | F9: 0 | I9: =D9*C9 -> 0.24077825 | J9: =I9+J8 -> 1.2569507
A10: 9 | B10: 41282 | C10: =B10-B9 -> 1 | D10: 0.31749283 | E10: 2013 | F10: 0 | I10: =D10*C10 -> 0.31749283 | J10: =I10+J9 -> 1.5744435
A11: 10 | B11: 41283 | C11: =B11-B10 -> 1 | D11: 0.45287389 | E11: 2013 | F11: 0 | I11: =D11*C11 -> 0.45287389 | J11: =I11+J10 -> 2.0273174
A12: 11 | B12: 41284 | C12: =B12-B11 -> 1 | D12: 0.51621977 | E12: 2013 | F12: 0 | I12: =D12*C12 -> 0.51621977 | J12: =I12+J11 -> 2.5435371
A13: 12 | B13: 41285 | C13: =B13-B12 -> 1 | D13: 0.31304548 | E13: 2013 | F13: 0 | I13: =D13*C13 -> 0.31304548 | J13: =I13+J12 -> 2.8565826
A14: 13 | B14: 41286 | C14: =B14-B13 -> 1 | D14: 0.1221572 | E14: 2013 | F14: 0 | I14: =D14*C14 -> 0.1221572 | J14: =I14+J13 -> 2.9787398
A15: 14 | B15: 41287 | C15: =B15-B14 -> 1 | D15: 0.1505806 | E15: 2013 | F15: 0 | I15: =D15*C15 -> 0.1505806 | J15: =I15+J14 -> 3.1293204
... A247: 366 | B247: 41639 | C247: =B247-B246 -> 1 | D247: 0.11498517 | E247: 2013 | F247: 0 | I247: =D247*C247 -> 0.11498517 | J247: =I247+J246 -> 237.4073

Sheet Лист23
A1: X | B1: date | D1: meanRECO | E1: year | F1: max_pulse_duration
A2: 27 | B2: 41300 | D2: 0.50289864 | E2: 2013 | F2: 8 | I2: 0.50289864
A3: 28 | B3: 41301 | C3: =B3-B2 -> 1 | D3: 0.40106498 | E3: 2013 | F3: 8 | I3: =C3*D3 -> 0.40106498 | J3: =I3+I2 -> 0.90396362
A4: 29 | B4: 41302 | C4: =B4-B3 -> 1 | D4: 0.42182578 | E4: 2013 | F4: 8 | I4: =C4*D4 -> 0.42182578 | J4: =J3+I4 -> 1.3257894
A5: 30 | B5: 41303 | C5: =B5-B4 -> 1 | D5: 0.17188298 | E5: 2013 | F5: 8 | I5: =C5*D5 -> 0.17188298 | J5: =J4+I5 -> 1.4976724
A6: 31 | B6: 41304 | C6: =B6-B5 -> 1 | D6: 0.22485991 | E6: 2013 | F6: 8 | I6: =C6*D6 -> 0.22485991 | J6: =J5+I6 -> 1.7225323
A7: 32 | B7: 41305 | C7: =B7-B6 -> 1 | D7: 0.23716898 | E7: 2013 | F7: 8 | I7: =C7*D7 -> 0.23716898 | J7: =J6+I7 -> 1.9597013
A8: 33 | B8: 41306 | C8: =B8-B7 -> 1 | D8: 0.25044289 | E8: 2013 | F8: 8 | I8: =C8*D8 -> 0.25044289 | J8: =J7+I8 -> 2.2101442
A9: 34 | B9: 41307 | C9: =B9-B8 -> 1 | D9: 0.38981368 | E9: 2013 | F9: 8 | I9: =C9*D9 -> 0.38981368 | J9: =J8+I9 -> 2.5999578
A10: 53 | B10: 41326 | C10: =B10-B9 -> 19 | D10: 0.15450577 | E10: 2013 | F10: 8 | I10: =C10*D10 -> 2.9356097 | J10: =J9+I10 -> 5.5355676
A11: 54 | B11: 41327 | C11: =B11-B10 -> 1 | D11: 0.26010427 | E11: 2013 | F11: 8 | I11: =C11*D11 -> 0.26010427 | J11: =J10+I11 -> 5.7956718
A12: 55 | B12: 41328 | C12: =B12-B11 -> 1 | D12: 0.2620749 | E12: 2013 | F12: 8 | I12: =C12*D12 -> 0.2620749 | J12: =J11+I12 -> 6.0577467
A13: 56 | B13: 41329 | C13: =B13-B12 -> 1 | D13: 0.16250078 | E13: 2013 | F13: 8 | I13: =C13*D13 -> 0.16250078 | J13: =J12+I13 -> 6.2202475
A14: 57 | B14: 41330 | C14: =B14-B13 -> 1 | D14: 0.111212 | E14: 2013 | F14: 8 | I14: =C14*D14 -> 0.111212 | J14: =J13+I14 -> 6.3314595 | Q14: 240
A15: 58 | B15: 41331 | C15: =B15-B14 -> 1 | D15: 0.13617076 | E15: 2013 | F15: 8 | I15: =C15*D15 -> 0.13617076 | J15: =J14+I15 -> 6.4676303 | Q15: 455 | R15: 695 | S15: =Q15*100/R15 -> 65.467626
A16: 59 | B16: 41332 | C16: =B16-B15 -> 1 | D16: 0.10534294 | E16: 2013 | F16: 8 | I16: =C16*D16 -> 0.10534294 | J16: =J15+I16 -> 6.5729732
A17: 60 | B17: 41333 | C17: =B17-B16 -> 1 | D17: 0.17898442 | E17: 2013 | F17: 8 | I17: =C17*D17 -> 0.17898442 | J17: =J16+I17 -> 6.7519576
A18: 68 | B18: 41341 | C18: =B18-B17 -> 8 | D18: 0.27262754 | E18: 2013 | F18: 8 | I18: =C18*D18 -> 2.1810203 | J18: =J17+I18 -> 8.932978
A19: 69 | B19: 41342 | C19: =B19-B18 -> 1 | D19: 0.22364949 | E19: 2013 | F19: 8 | I19: =C19*D19 -> 0.22364949 | J19: =J18+I19 -> 9.1566274
A20: 70 | B20: 41343 | C20: =B20-B19 -> 1 | D20: 0.17965329 | E20: 2013 | F20: 8 | I20: =C20*D20 -> 0.17965329 | J20: =J19+I20 -> 9.3362807
A21: 71 | B21: 41344 | C21: =B21-B20 -> 1 | D21: 0.27395005 | E21: 2013 | F21: 8 | I21: =C21*D21 -> 0.27395005 | J21: =J20+I21 -> 9.6102308
A22: 72 | B22: 41345 | C22: =B22-B21 -> 1 | D22: 0.30227154 | E22: 2013 | F22: 8 | I22: =C22*D22 -> 0.30227154 | J22: =J21+I22 -> 9.9125023
A23: 73 | B23: 41346 | C23: =B23-B22 -> 1 | D23: 0.3359982 | E23: 2013 | F23: 8 | I23: =C23*D23 -> 0.3359982 | J23: =J22+I23 -> 10.248501
A24: 74 | B24: 41347 | C24: =B24-B23 -> 1 | D24: 0.4112999 | E24: 2013 | F24: 8 | I24: =C24*D24 -> 0.4112999 | J24: =J23+I24 -> 10.6598
A25: 75 | B25: 41348 | C25: =B25-B24 -> 1 | D25: 0.56792593 | E25: 2013 | F25: 8 | I25: =C25*D25 -> 0.56792593 | J25: =J24+I25 -> 11.227726
A26: 190 | B26: 41463 | C26: =B26-B25 -> 115 | D26: 2.224644 | E26: 2013 | F26: 8 | I26: =C26*D26 -> 255.83405 | J26: =J25+I26 -> 267.06178
A27: 191 | B27: 41464 | C27: =B27-B26 -> 1 | D27: 2.4186247 | E27: 2013 | F27: 20 | I27: =C27*D27 -> 2.4186247 | J27: =J26+I27 -> 269.48041
... A119: 335 | B119: 41608 | C119: =B119-B118 -> 1 | D119: 0.47261052 | E119: 2013 | F119: 8 | I119: =C119*D119 -> 0.47261052 | J119: =J118+I119 -> 454.92514

Sheet 14
A1: X | B1: date | C1: meanRECO | D1: year | E1: max_pulse_duration
A2: 367 | B2: 41640 | C2: 0.13624603 | D2: 2014 | E2: 0
A3: 368 | B3: 41641 | C3: 0.16172815 | D3: 2014 | E3: 0
A4: 369 | B4: 41642 | C4: 0.079093752 | D4: 2014 | E4: 0
A5: 370 | B5: 41643 | C5: 0.1024647 | D5: 2014 | E5: 0
A6: 371 | B6: 41644 | C6: 0.091812892 | D6: 2014 | E6: 0
A7: 372 | B7: 41645 | C7: 0.084196336 | D7: 2014 | E7: 0
A8: 373 | B8: 41646 | C8: 0.092028252 | D8: 2014 | E8: 0
A9: 374 | B9: 41647 | C9: 0.10445786 | D9: 2014 | E9: 0
A10: 375 | B10: 41648 | C10: 0.1052611 | D10: 2014 | E10: 0
A11: 376 | B11: 41649 | C11: 0.1220117 | D11: 2014 | E11: 0
A12: 377 | B12: 41650 | C12: 0.14341396 | D12: 2014 | E12: 0
A13: 378 | B13: 41651 | C13: 0.14762407 | D13: 2014 | E13: 0
... A366: 731 | B366: 42004 | C366: 0.3424546 | D366: 2014 | E366: 0

Sheet Лист22
A1: X | B1: date | D1: meanRECO | E1: year | F1: max_pulse_duration
A2: 367 | B2: 41640 | D2: 0.13624603 | E2: 2014 | F2: 0 | I2: 0.13624603
A3: 368 | B3: 41641 | C3: =B3-B2 -> 1 | D3: 0.16172815 | E3: 2014 | F3: 0 | I3: =D3*C3 -> 0.16172815 | J3: =I3+I2 -> 0.29797419
A4: 369 | B4: 41642 | C4: =B4-B3 -> 1 | D4: 0.079093752 | E4: 2014 | F4: 0 | I4: =D4*C4 -> 0.079093752 | J4: =I4+J3 -> 0.37706794
A5: 370 | B5: 41643 | C5: =B5-B4 -> 1 | D5: 0.1024647 | E5: 2014 | F5: 0 | I5: =D5*C5 -> 0.1024647 | J5: =I5+J4 -> 0.47953264
A6: 371 | B6: 41644 | C6: =B6-B5 -> 1 | D6: 0.091812892 | E6: 2014 | F6: 0 | I6: =D6*C6 -> 0.091812892 | J6: =I6+J5 -> 0.57134553
A7: 372 | B7: 41645 | C7: =B7-B6 -> 1 | D7: 0.084196336 | E7: 2014 | F7: 0 | I7: =D7*C7 -> 0.084196336 | J7: =I7+J6 -> 0.65554187
A8: 373 | B8: 41646 | C8: =B8-B7 -> 1 | D8: 0.092028252 | E8: 2014 | F8: 0 | I8: =D8*C8 -> 0.092028252 | J8: =I8+J7 -> 0.74757012
A9: 374 | B9: 41647 | C9: =B9-B8 -> 1 | D9: 0.10445786 | E9: 2014 | F9: 0 | I9: =D9*C9 -> 0.10445786 | J9: =I9+J8 -> 0.85202798
A10: 375 | B10: 41648 | C10: =B10-B9 -> 1 | D10: 0.1052611 | E10: 2014 | F10: 0 | I10: =D10*C10 -> 0.1052611 | J10: =I10+J9 -> 0.95728908
A11: 376 | B11: 41649 | C11: =B11-B10 -> 1 | D11: 0.1220117 | E11: 2014 | F11: 0 | I11: =D11*C11 -> 0.1220117 | J11: =I11+J10 -> 1.0793008
A12: 377 | B12: 41650 | C12: =B12-B11 -> 1 | D12: 0.14341396 | E12: 2014 | F12: 0 | I12: =D12*C12 -> 0.14341396 | J12: =I12+J11 -> 1.2227147
A13: 378 | B13: 41651 | C13: =B13-B12 -> 1 | D13: 0.14762407 | E13: 2014 | F13: 0 | I13: =D13*C13 -> 0.14762407 | J13: =I13+J12 -> 1.3703388
A14: 379 | B14: 41652 | C14: =B14-B13 -> 1 | D14: 0.059188573 | E14: 2014 | F14: 0 | I14: =D14*C14 -> 0.059188573 | J14: =I14+J13 -> 1.4295274
A15: 380 | B15: 41653 | C15: =B15-B14 -> 1 | D15: 0.051449992 | E15: 2014 | F15: 0 | I15: =D15*C15 -> 0.051449992 | J15: =I15+J14 -> 1.4809774
... A227: 731 | B227: 42004 | C227: =B227-B226 -> 1 | D227: 0.3424546 | E227: 2014 | F227: 0 | I227: =D227*C227 -> 0.3424546 | J227: =I227+J226 -> 186.41542

Sheet Лист21
A1: X | B1: date | D1: meanRECO | E1: year | F1: max_pulse_duration
A2: 427 | B2: 41700 | D2: 0.68474085 | E2: 2014 | F2: 14 | I2: 0.68474085
A3: 428 | B3: 41701 | C3: =B3-B2 -> 1 | D3: 0.68750566 | E3: 2014 | F3: 14 | I3: =D3*C3 -> 0.68750566 | J3: =I3+I2 -> 1.3722465
A4: 429 | B4: 41702 | C4: =B4-B3 -> 1 | D4: 0.51791372 | E4: 2014 | F4: 14 | I4: =D4*C4 -> 0.51791372 | J4: =I4+J3 -> 1.8901602
A5: 430 | B5: 41703 | C5: =B5-B4 -> 1 | D5: 0.64659882 | E5: 2014 | F5: 14 | I5: =D5*C5 -> 0.64659882 | J5: =I5+J4 -> 2.5367591
A6: 431 | B6: 41704 | C6: =B6-B5 -> 1 | D6: 0.62416478 | E6: 2014 | F6: 14 | I6: =D6*C6 -> 0.62416478 | J6: =I6+J5 -> 3.1609238
A7: 432 | B7: 41705 | C7: =B7-B6 -> 1 | D7: 0.49973587 | E7: 2014 | F7: 14 | I7: =D7*C7 -> 0.49973587 | J7: =I7+J6 -> 3.6606597
A8: 433 | B8: 41706 | C8: =B8-B7 -> 1 | D8: 0.41121899 | E8: 2014 | F8: 14 | I8: =D8*C8 -> 0.41121899 | J8: =I8+J7 -> 4.0718787
A9: 434 | B9: 41707 | C9: =B9-B8 -> 1 | D9: 0.4182729 | E9: 2014 | F9: 14 | I9: =D9*C9 -> 0.4182729 | J9: =I9+J8 -> 4.4901516
A10: 435 | B10: 41708 | C10: =B10-B9 -> 1 | D10: 0.41359247 | E10: 2014 | F10: 14 | I10: =D10*C10 -> 0.41359247 | J10: =I10+J9 -> 4.9037441
A11: 436 | B11: 41709 | C11: =B11-B10 -> 1 | D11: 0.42426217 | E11: 2014 | F11: 14 | I11: =D11*C11 -> 0.42426217 | J11: =I11+J10 -> 5.3280062
A12: 437 | B12: 41710 | C12: =B12-B11 -> 1 | D12: 0.46615143 | E12: 2014 | F12: 14 | I12: =D12*C12 -> 0.46615143 | J12: =I12+J11 -> 5.7941577
A13: 438 | B13: 41711 | C13: =B13-B12 -> 1 | D13: 0.43753466 | E13: 2014 | F13: 14 | I13: =D13*C13 -> 0.43753466 | J13: =I13+J12 -> 6.2316923
A14: 439 | B14: 41712 | C14: =B14-B13 -> 1 | D14: 0.36634891 | E14: 2014 | F14: 14 | I14: =D14*C14 -> 0.36634891 | J14: =I14+J13 -> 6.5980412
A15: 440 | B15: 41713 | C15: =B15-B14 -> 1 | D15: 0.4029048 | E15: 2014 | F15: 14 | I15: =D15*C15 -> 0.4029048 | J15: =I15+J14 -> 7.000946
... A117: 651 | B117: 41924 | C117: =B117-B116 -> 1 | D117: 0.93411818 | E117: 2014 | F117: 20 | I117: =D117*C117 -> 0.93411818 | J117: =I117+J116 -> 346.72697
A118: 652 | B118: 41925 | C118: =B118-B117 -> 1 | D118: 0.9155281 | E118: 2014 | F118: 20 | I118: =D118*C118 -> 0.9155281 | J118: =I118+J117 -> 347.6425 | P118: 185
A119: 653 | B119: 41926 | C119: =B119-B118 -> 1 | D119: 0.9828407 | E119: 2014 | F119: 20 | I119: =D119*C119 -> 0.9828407 | J119: =I119+J118 -> 348.62534 | P119: 380 | Q119: 565 | R119: =P119*100/Q119 -> 67.256637
A120: 654 | B120: 41927 | C120: =B120-B119 -> 1 | D120: 1.1072704 | E120: 2014 | F120: 20 | I120: =D120*C120 -> 1.1072704 | J120: =I120+J119 -> 349.73261
A121: 655 | B121: 41928 | C121: =B121-B120 -> 1 | D121: 1.0942175 | E121: 2014 | F121: 20 | I121: =D121*C121 -> 1.0942175 | J121: =I121+J120 -> 350.82683
A122: 656 | B122: 41929 | C122: =B122-B121 -> 1 | D122: 1.0462305 | E122: 2014 | F122: 20 | I122: =D122*C122 -> 1.0462305 | J122: =I122+J121 -> 351.87306
A123: 657 | B123: 41930 | C123: =B123-B122 -> 1 | D123: 1.082383 | E123: 2014 | F123: 20 | I123: =D123*C123 -> 1.082383 | J123: =I123+J122 -> 352.95544
A124: 658 | B124: 41931 | C124: =B124-B123 -> 1 | D124: 1.0882929 | E124: 2014 | F124: 20 | I124: =D124*C124 -> 1.0882929 | J124: =I124+J123 -> 354.04373
A125: 659 | B125: 41932 | C125: =B125-B124 -> 1 | D125: 1.0054889 | E125: 2014 | F125: 20 | I125: =D125*C125 -> 1.0054889 | J125: =I125+J124 -> 355.04922
A126: 660 | B126: 41933 | C126: =B126-B125 -> 1 | D126: 0.93134446 | E126: 2014 | F126: 20 | I126: =D126*C126 -> 0.93134446 | J126: =I126+J125 -> 355.98057
A127: 661 | B127: 41934 | C127: =B127-B126 -> 1 | D127: 0.8276522 | E127: 2014 | F127: 20 | I127: =D127*C127 -> 0.8276522 | J127: =I127+J126 -> 356.80822
A128: 662 | B128: 41935 | C128: =B128-B127 -> 1 | D128: 0.71455617 | E128: 2014 | F128: 20 | I128: =D128*C128 -> 0.71455617 | J128: =I128+J127 -> 357.52277
A129: 663 | B129: 41936 | C129: =B129-B128 -> 1 | D129: 0.70896262 | E129: 2014 | F129: 20 | I129: =D129*C129 -> 0.70896262 | J129: =I129+J128 -> 358.23174
A130: 664 | B130: 41937 | C130: =B130-B129 -> 1 | D130: 0.80234399 | E130: 2014 | F130: 20 | I130: =D130*C130 -> 0.80234399 | J130: =I130+J129 -> 359.03408
A131: 665 | B131: 41938 | C131: =B131-B130 -> 1 | D131: 0.82746677 | E131: 2014 | F131: 20 | I131: =D131*C131 -> 0.82746677 | J131: =I131+J130 -> 359.86155
... A140: 720 | B140: 41993 | C140: =B140-B139 -> 1 | D140: 0.26231695 | E140: 2014 | F140: 8 | I140: =D140*C140 -> 0.26231695 | J140: =I140+J139 -> 381.03794

Sheet 15
A1: X | B1: date | C1: meanRECO | D1: year | E1: max_pulse_duration
A2: 732 | B2: 42005 | C2: 0.19643602 | D2: 2015 | E2: 0
A3: 733 | B3: 42006 | C3: 0.15128296 | D3: 2015 | E3: 0
A4: 734 | B4: 42007 | C4: 0.15589321 | D4: 2015 | E4: 0
A5: 735 | B5: 42008 | C5: 0.13625157 | D5: 2015 | E5: 0
A6: 736 | B6: 42009 | C6: 0.1459369 | D6: 2015 | E6: 0
A7: 737 | B7: 42010 | C7: 0.22946433 | D7: 2015 | E7: 0
A8: 738 | B8: 42011 | C8: 0.24440597 | D8: 2015 | E8: 0
A9: 739 | B9: 42012 | C9: 0.23930157 | D9: 2015 | E9: 0
A10: 740 | B10: 42013 | C10: 0.34717462 | D10: 2015 | E10: 0
A11: 741 | B11: 42014 | C11: 0.24170861 | D11: 2015 | E11: 0
A12: 742 | B12: 42015 | C12: 0.32578748 | D12: 2015 | E12: 0
A13: 743 | B13: 42016 | C13: 0.28658958 | D13: 2015 | E13: 0
... A366: 1096 | B366: 42369 | C366: 0.1019766 | D366: 2015 | E366: 0

Sheet Лист20
A1: X | B1: date | D1: meanRECO | E1: year | F1: max_pulse_duration
A2: 732 | B2: 42005 | D2: 0.19643602 | E2: 2015 | F2: 0 | I2: 0.19643602
A3: 733 | B3: 42006 | C3: =B3-B2 -> 1 | D3: 0.15128296 | E3: 2015 | F3: 0 | I3: =D3*C3 -> 0.15128296 | J3: =I3+I2 -> 0.34771898
A4: 734 | B4: 42007 | C4: =B4-B3 -> 1 | D4: 0.15589321 | E4: 2015 | F4: 0 | I4: =D4*C4 -> 0.15589321 | J4: =I4+J3 -> 0.50361219
A5: 735 | B5: 42008 | C5: =B5-B4 -> 1 | D5: 0.13625157 | E5: 2015 | F5: 0 | I5: =D5*C5 -> 0.13625157 | J5: =I5+J4 -> 0.63986376
A6: 736 | B6: 42009 | C6: =B6-B5 -> 1 | D6: 0.1459369 | E6: 2015 | F6: 0 | I6: =D6*C6 -> 0.1459369 | J6: =I6+J5 -> 0.78580066
A7: 737 | B7: 42010 | C7: =B7-B6 -> 1 | D7: 0.22946433 | E7: 2015 | F7: 0 | I7: =D7*C7 -> 0.22946433 | J7: =I7+J6 -> 1.015265
A8: 738 | B8: 42011 | C8: =B8-B7 -> 1 | D8: 0.24440597 | E8: 2015 | F8: 0 | I8: =D8*C8 -> 0.24440597 | J8: =I8+J7 -> 1.259671
A9: 739 | B9: 42012 | C9: =B9-B8 -> 1 | D9: 0.23930157 | E9: 2015 | F9: 0 | I9: =D9*C9 -> 0.23930157 | J9: =I9+J8 -> 1.4989725
A10: 740 | B10: 42013 | C10: =B10-B9 -> 1 | D10: 0.34717462 | E10: 2015 | F10: 0 | I10: =D10*C10 -> 0.34717462 | J10: =I10+J9 -> 1.8461472
A11: 741 | B11: 42014 | C11: =B11-B10 -> 1 | D11: 0.24170861 | E11: 2015 | F11: 0 | I11: =D11*C11 -> 0.24170861 | J11: =I11+J10 -> 2.0878558
A12: 742 | B12: 42015 | C12: =B12-B11 -> 1 | D12: 0.32578748 | E12: 2015 | F12: 0 | I12: =D12*C12 -> 0.32578748 | J12: =I12+J11 -> 2.4136432
A13: 743 | B13: 42016 | C13: =B13-B12 -> 1 | D13: 0.28658958 | E13: 2015 | F13: 0 | I13: =D13*C13 -> 0.28658958 | J13: =I13+J12 -> 2.7002328
A14: 744 | B14: 42017 | C14: =B14-B13 -> 1 | D14: 0.30258036 | E14: 2015 | F14: 0 | I14: =D14*C14 -> 0.30258036 | J14: =I14+J13 -> 3.0028132
A15: 745 | B15: 42018 | C15: =B15-B14 -> 1 | D15: 0.30263187 | E15: 2015 | F15: 0 | I15: =D15*C15 -> 0.30263187 | J15: =I15+J14 -> 3.305445
... A190: 1096 | B190: 42369 | C190: =B190-B189 -> 1 | D190: 0.1019766 | E190: 2015 | F190: 0 | I190: =D190*C190 -> 0.1019766 | J190: =I190+J189 -> 310.85864

Sheet Лист19
A1: X | B1: date | D1: meanRECO | E1: year | F1: max_pulse_duration
A2: 761 | B2: 42034 | D2: 0.02566606 | E2: 2015 | F2: 20 | I2: 0.02566606
A3: 762 | B3: 42035 | C3: =B3-B2 -> 1 | D3: 0.051059645 | E3: 2015 | F3: 20 | I3: =D3*C3 -> 0.051059645 | J3: =I3+I2 -> 0.076725705
A4: 763 | B4: 42036 | C4: =B4-B3 -> 1 | D4: 0.14026087 | E4: 2015 | F4: 20 | I4: =D4*C4 -> 0.14026087 | J4: =I4+J3 -> 0.21698658
A5: 764 | B5: 42037 | C5: =B5-B4 -> 1 | D5: 0.092595806 | E5: 2015 | F5: 20 | I5: =D5*C5 -> 0.092595806 | J5: =I5+J4 -> 0.30958238
A6: 765 | B6: 42038 | C6: =B6-B5 -> 1 | D6: 0.13226145 | E6: 2015 | F6: 20 | I6: =D6*C6 -> 0.13226145 | J6: =I6+J5 -> 0.44184383
A7: 766 | B7: 42039 | C7: =B7-B6 -> 1 | D7: 0.10957236 | E7: 2015 | F7: 20 | I7: =D7*C7 -> 0.10957236 | J7: =I7+J6 -> 0.5514162
A8: 767 | B8: 42040 | C8: =B8-B7 -> 1 | D8: 0.13385796 | E8: 2015 | F8: 20 | I8: =D8*C8 -> 0.13385796 | J8: =I8+J7 -> 0.68527415
A9: 768 | B9: 42041 | C9: =B9-B8 -> 1 | D9: 0.20018598 | E9: 2015 | F9: 20 | I9: =D9*C9 -> 0.20018598 | J9: =I9+J8 -> 0.88546014
A10: 769 | B10: 42042 | C10: =B10-B9 -> 1 | D10: 0.19769956 | E10: 2015 | F10: 20 | I10: =D10*C10 -> 0.19769956 | J10: =I10+J9 -> 1.0831597
A11: 770 | B11: 42043 | C11: =B11-B10 -> 1 | D11: 0.24871616 | E11: 2015 | F11: 20 | I11: =D11*C11 -> 0.24871616 | J11: =I11+J10 -> 1.3318759
A12: 771 | B12: 42044 | C12: =B12-B11 -> 1 | D12: 0.29666524 | E12: 2015 | F12: 20 | I12: =D12*C12 -> 0.29666524 | J12: =I12+J11 -> 1.6285411
A13: 772 | B13: 42045 | C13: =B13-B12 -> 1 | D13: 0.35134865 | E13: 2015 | F13: 20 | I13: =D13*C13 -> 0.35134865 | J13: =I13+J12 -> 1.9798898
A14: 773 | B14: 42046 | C14: =B14-B13 -> 1 | D14: 0.30723691 | E14: 2015 | F14: 20 | I14: =D14*C14 -> 0.30723691 | J14: =I14+J13 -> 2.2871267
A15: 774 | B15: 42047 | C15: =B15-B14 -> 1 | D15: 0.24900621 | E15: 2015 | F15: 20 | I15: =D15*C15 -> 0.24900621 | J15: =I15+J14 -> 2.5361329
... A143: 1006 | B143: 42279 | C143: =B143-B142 -> 1 | D143: 0.96892756 | E143: 2015 | F143: 14 | I143: =D143*C143 -> 0.96892756 | J143: =I143+J142 -> 471.10894
A144: 1007 | B144: 42280 | C144: =B144-B143 -> 1 | D144: 0.9955176 | E144: 2015 | F144: 14 | I144: =D144*C144 -> 0.9955176 | J144: =I144+J143 -> 472.10446 | Q144: 310
A145: 1008 | B145: 42281 | C145: =B145-B144 -> 1 | D145: 1.0485283 | E145: 2015 | F145: 14 | I145: =D145*C145 -> 1.0485283 | J145: =I145+J144 -> 473.15299 | Q145: 530 | R145: 840 | S145: =Q145*100/R145 -> 63.095238
A146: 1009 | B146: 42282 | C146: =B146-B145 -> 1 | D146: 1.0245829 | E146: 2015 | F146: 14 | I146: =D146*C146 -> 1.0245829 | J146: =I146+J145 -> 474.17757
A147: 1021 | B147: 42294 | C147: =B147-B146 -> 12 | D147: 1.4132463 | E147: 2015 | F147: 14 | I147: =D147*C147 -> 16.958956 | J147: =I147+J146 -> 491.13653
A148: 1022 | B148: 42295 | C148: =B148-B147 -> 1 | D148: 1.4076572 | E148: 2015 | F148: 14 | I148: =D148*C148 -> 1.4076572 | J148: =I148+J147 -> 492.54419
A149: 1023 | B149: 42296 | C149: =B149-B148 -> 1 | D149: 1.4221836 | E149: 2015 | F149: 14 | I149: =D149*C149 -> 1.4221836 | J149: =I149+J148 -> 493.96637
A150: 1024 | B150: 42297 | C150: =B150-B149 -> 1 | D150: 1.2065717 | E150: 2015 | F150: 14 | I150: =D150*C150 -> 1.2065717 | J150: =I150+J149 -> 495.17294
A151: 1025 | B151: 42298 | C151: =B151-B150 -> 1 | D151: 0.97606711 | E151: 2015 | F151: 14 | I151: =D151*C151 -> 0.97606711 | J151: =I151+J150 -> 496.14901
A152: 1026 | B152: 42299 | C152: =B152-B151 -> 1 | D152: 0.908481 | E152: 2015 | F152: 14 | I152: =D152*C152 -> 0.908481 | J152: =I152+J151 -> 497.05749
A153: 1027 | B153: 42300 | C153: =B153-B152 -> 1 | D153: 0.96324694 | E153: 2015 | F153: 14 | I153: =D153*C153 -> 0.96324694 | J153: =I153+J152 -> 498.02074
A154: 1028 | B154: 42301 | C154: =B154-B153 -> 1 | D154: 1.0365818 | E154: 2015 | F154: 14 | I154: =D154*C154 -> 1.0365818 | J154: =I154+J153 -> 499.05732
A155: 1029 | B155: 42302 | C155: =B155-B154 -> 1 | D155: 0.97998342 | E155: 2015 | F155: 14 | I155: =D155*C155 -> 0.97998342 | J155: =I155+J154 -> 500.0373
A156: 1030 | B156: 42303 | C156: =B156-B155 -> 1 | D156: 0.99359923 | E156: 2015 | F156: 14 | I156: =D156*C156 -> 0.99359923 | J156: =I156+J155 -> 501.0309
A157: 1031 | B157: 42304 | C157: =B157-B156 -> 1 | D157: 0.92063009 | E157: 2015 | F157: 14 | I157: =D157*C157 -> 0.92063009 | J157: =I157+J156 -> 501.95153
... A177: 1084 | B177: 42357 | C177: =B177-B176 -> 1 | D177: 0.37500254 | E177: 2015 | F177: 8 | I177: =D177*C177 -> 0.37500254 | J177: =I177+J176 -> 533.95701

Sheet 16
A1: X | B1: date | C1: meanRECO | D1: year | E1: max_pulse_duration
A2: 1097 | B2: 42370 | C2: 0.24685637 | D2: 2016 | E2: 0
A3: 1098 | B3: 42371 | C3: 0.23250731 | D3: 2016 | E3: 0
A4: 1099 | B4: 42372 | C4: 0.27568291 | D4: 2016 | E4: 0
A5: 1100 | B5: 42373 | C5: 0.29297858 | D5: 2016 | E5: 0
A6: 1101 | B6: 42374 | C6: 0.29915901 | D6: 2016 | E6: 14
A7: 1102 | B7: 42375 | C7: 0.40820691 | D7: 2016 | E7: 14
A8: 1103 | B8: 42376 | C8: 0.25194044 | D8: 2016 | E8: 14
A9: 1104 | B9: 42377 | C9: 0.19080099 | D9: 2016 | E9: 14
A10: 1105 | B10: 42378 | C10: 0.22022178 | D10: 2016 | E10: 14
A11: 1106 | B11: 42379 | C11: 0.2152847 | D11: 2016 | E11: 14
A12: 1107 | B12: 42380 | C12: 0.23024027 | D12: 2016 | E12: 14
A13: 1108 | B13: 42381 | C13: 0.27845222 | D13: 2016 | E13: 14
... A364: 1461 | B364: 42734 | C364: 0.37506647 | D364: 2016 | E364: 14

Sheet Лист18
A1: X | B1: date | D1: meanRECO | E1: year | F1: max_pulse_duration
A2: 1097 | B2: 42370 | D2: 0.24685637 | E2: 2016 | F2: 0 | I2: 0.24685637
A3: 1098 | B3: 42371 | C3: =B3-B2 -> 1 | D3: 0.23250731 | E3: 2016 | F3: 0 | I3: =D3*C3 -> 0.23250731 | J3: =I3+I2 -> 0.47936368
A4: 1099 | B4: 42372 | C4: =B4-B3 -> 1 | D4: 0.27568291 | E4: 2016 | F4: 0 | I4: =D4*C4 -> 0.27568291 | J4: =I46+J3 -> 1.1893541
A5: 1100 | B5: 42373 | C5: =B5-B4 -> 1 | D5: 0.29297858 | E5: 2016 | F5: 0 | I5: =D5*C5 -> 0.29297858 | J5: =I47+J4 -> 1.6174308
A6: 1119 | B6: 42392 | C6: =B6-B5 -> 19 | D6: 0.16915027 | E6: 2016 | F6: 0 | I6: =D6*C6 -> 3.2138551 | J6: =I48+J5 -> 2.0332984
A7: 1120 | B7: 42393 | C7: =B7-B6 -> 1 | D7: 0.24938301 | E7: 2016 | F7: 0 | I7: =D7*C7 -> 0.24938301 | J7: =I49+J6 -> 2.3076452
A8: 1121 | B8: 42394 | C8: =B8-B7 -> 1 | D8: 0.19341191 | E8: 2016 | F8: 0 | I8: =D8*C8 -> 0.19341191 | J8: =I50+J7 -> 3.1836303
A9: 1122 | B9: 42395 | C9: =B9-B8 -> 1 | D9: 0.15849575 | E9: 2016 | F9: 0 | I9: =D9*C9 -> 0.15849575 | J9: =I51+J8 -> 3.3878967
A10: 1123 | B10: 42396 | C10: =B10-B9 -> 1 | D10: 0.21547777 | E10: 2016 | F10: 0 | I10: =D10*C10 -> 0.21547777 | J10: =I52+J9 -> 3.6463983
A11: 1124 | B11: 42397 | C11: =B11-B10 -> 1 | D11: 0.41119993 | E11: 2016 | F11: 0 | I11: =D11*C11 -> 0.41119993 | J11: =I53+J10 -> 4.1214779
A12: 1125 | B12: 42398 | C12: =B12-B11 -> 1 | D12: 0.52955375 | E12: 2016 | F12: 0 | I12: =D12*C12 -> 0.52955375 | J12: =I54+J11 -> 4.9525453
A13: 1126 | B13: 42399 | C13: =B13-B12 -> 1 | D13: 0.64917603 | E13: 2016 | F13: 0 | I13: =D13*C13 -> 0.64917603 | J13: =I55+J12 -> 6.1524342
A14: 1127 | B14: 42400 | C14: =B14-B13 -> 1 | D14: 0.85151327 | E14: 2016 | F14: 0 | I14: =D14*C14 -> 0.85151327 | J14: =I56+J13 -> 6.7769297
A15: 1136 | B15: 42409 | C15: =B15-B14 -> 9 | D15: 0.16605841 | E15: 2016 | F15: 0 | I15: =D15*C15 -> 1.4945257 | J15: =I57+J14 -> 6.9923053
... A229: 1453 | B229: 42726 | C229: =B229-B228 -> 1 | D229: 0.71439237 | E229: 2016 | F229: 0 | I229: =D229*C229 -> 0.71439237 | J229: =I271+J228 -> 250.69197

Sheet Лист17
A1: X | B1: date | D1: meanRECO | E1: year | F1: max_pulse_duration
A2: 1101 | B2: 42374 | D2: 0.29915901 | E2: 2016 | F2: 14 | I2: 0.29915901
A3: 1102 | B3: 42375 | C3: =B3-B2 -> 1 | D3: 0.40820691 | E3: 2016 | F3: 14 | I3: =D3*C3 -> 0.40820691 | J3: =I3+I2 -> 0.70736592
A4: 1103 | B4: 42376 | C4: =B4-B3 -> 1 | D4: 0.25194044 | E4: 2016 | F4: 14 | I4: =D4*C4 -> 0.25194044 | J4: =J3+I4 -> 0.95930636
A5: 1104 | B5: 42377 | C5: =B5-B4 -> 1 | D5: 0.19080099 | E5: 2016 | F5: 14 | I5: =D5*C5 -> 0.19080099 | J5: =J4+I5 -> 1.1501073
A6: 1105 | B6: 42378 | C6: =B6-B5 -> 1 | D6: 0.22022178 | E6: 2016 | F6: 14 | I6: =D6*C6 -> 0.22022178 | J6: =J5+I6 -> 1.3703291
A7: 1106 | B7: 42379 | C7: =B7-B6 -> 1 | D7: 0.2152847 | E7: 2016 | F7: 14 | I7: =D7*C7 -> 0.2152847 | J7: =J6+I7 -> 1.5856138
A8: 1107 | B8: 42380 | C8: =B8-B7 -> 1 | D8: 0.23024027 | E8: 2016 | F8: 14 | I8: =D8*C8 -> 0.23024027 | J8: =J7+I8 -> 1.8158541
A9: 1108 | B9: 42381 | C9: =B9-B8 -> 1 | D9: 0.27845222 | E9: 2016 | F9: 14 | I9: =D9*C9 -> 0.27845222 | J9: =J8+I9 -> 2.0943063
A10: 1109 | B10: 42382 | C10: =B10-B9 -> 1 | D10: 0.3138477 | E10: 2016 | F10: 14 | I10: =D10*C10 -> 0.3138477 | J10: =J9+I10 -> 2.408154
A11: 1110 | B11: 42383 | C11: =B11-B10 -> 1 | D11: 0.32114821 | E11: 2016 | F11: 14 | I11: =D11*C11 -> 0.32114821 | J11: =J10+I11 -> 2.7293022
A12: 1111 | B12: 42384 | C12: =B12-B11 -> 1 | D12: 0.39104897 | E12: 2016 | F12: 14 | I12: =D12*C12 -> 0.39104897 | J12: =J11+I12 -> 3.1203512
A13: 1112 | B13: 42385 | C13: =B13-B12 -> 1 | D13: 0.28487951 | E13: 2016 | F13: 14 | I13: =D13*C13 -> 0.28487951 | J13: =J12+I13 -> 3.4052307
A14: 1113 | B14: 42386 | C14: =B14-B13 -> 1 | D14: 0.26768966 | E14: 2016 | F14: 14 | I14: =D14*C14 -> 0.26768966 | J14: =J13+I14 -> 3.6729204
A15: 1114 | B15: 42387 | C15: =B15-B14 -> 1 | D15: 0.25155078 | E15: 2016 | F15: 14 | I15: =D15*C15 -> 0.25155078 | J15: =J14+I15 -> 3.9244712
... A20: 1128 | B20: 42401 | C20: =B20-B19 -> 10 | D20: 0.68123153 | E20: 2016 | F20: 8 | I20: =D20*C20 -> 6.8123153 | J20: =J19+I20 -> 11.47818
A21: 1129 | B21: 42402 | C21: =B21-B20 -> 1 | D21: 0.37721686 | E21: 2016 | F21: 8 | I21: =D21*C21 -> 0.37721686 | J21: =J20+I21 -> 11.855397 | Q21: 250
A22: 1130 | B22: 42403 | C22: =B22-B21 -> 1 | D22: 0.36480508 | E22: 2016 | F22: 8 | I22: =D22*C22 -> 0.36480508 | J22: =J21+I22 -> 12.220202 | Q22: 600 | R22: 850 | S22: =Q22*100/R22 -> 70.588235
A23: 1131 | B23: 42404 | C23: =B23-B22 -> 1 | D23: 0.37291167 | E23: 2016 | F23: 8 | I23: =D23*C23 -> 0.37291167 | J23: =J22+I23 -> 12.593114
A24: 1132 | B24: 42405 | C24: =B24-B23 -> 1 | D24: 0.26618021 | E24: 2016 | F24: 8 | I24: =D24*C24 -> 0.26618021 | J24: =J23+I24 -> 12.859294
A25: 1133 | B25: 42406 | C25: =B25-B24 -> 1 | D25: 0.17088306 | E25: 2016 | F25: 8 | I25: =D25*C25 -> 0.17088306 | J25: =J24+I25 -> 13.030177
A26: 1134 | B26: 42407 | C26: =B26-B25 -> 1 | D26: 0.16399289 | E26: 2016 | F26: 8 | I26: =D26*C26 -> 0.16399289 | J26: =J25+I26 -> 13.19417
A27: 1135 | B27: 42408 | C27: =B27-B26 -> 1 | D27: 0.17000308 | E27: 2016 | F27: 8 | I27: =D27*C27 -> 0.17000308 | J27: =J26+I27 -> 13.364173
A28: 1277 | B28: 42550 | C28: =B28-B27 -> 142 | D28: 2.4168822 | E28: 2016 | F28: 20 | I28: =D28*C28 -> 343.19728 | J28: =J27+I28 -> 356.56145
A29: 1278 | B29: 42551 | C29: =B29-B28 -> 1 | D29: 2.1706025 | E29: 2016 | F29: 20 | I29: =D29*C29 -> 2.1706025 | J29: =J28+I29 -> 358.73205
A30: 1279 | B30: 42552 | C30: =B30-B29 -> 1 | D30: 1.9063121 | E30: 2016 | F30: 20 | I30: =D30*C30 -> 1.9063121 | J30: =J29+I30 -> 360.63836
A31: 1280 | B31: 42553 | C31: =B31-B30 -> 1 | D31: 1.9255106 | E31: 2016 | F31: 20 | I31: =D31*C31 -> 1.9255106 | J31: =J30+I31 -> 362.56387
A32: 1281 | B32: 42554 | C32: =B32-B31 -> 1 | D32: 1.7573844 | E32: 2016 | F32: 20 | I32: =D32*C32 -> 1.7573844 | J32: =J31+I32 -> 364.32126
A33: 1282 | B33: 42555 | C33: =B33-B32 -> 1 | D33: 1.584819 | E33: 2016 | F33: 20 | I33: =D33*C33 -> 1.584819 | J33: =J32+I33 -> 365.90608
A34: 1283 | B34: 42556 | C34: =B34-B33 -> 1 | D34: 1.4965539 | E34: 2016 | F34: 20 | I34: =D34*C34 -> 1.4965539 | J34: =J33+I34 -> 367.40263
... A136: 1461 | B136: 42734 | C136: =B136-B135 -> 1 | D136: 0.37506647 | E136: 2016 | F136: 14 | I136: =D136*C136 -> 0.37506647 | J136: =J135+I136 -> 601.7561

Sheet 17
A1: X | B1: date | C1: meanRECO | D1: year | E1: max_pulse_duration
A2: 1463 | B2: 42736 | C2: 0.25971469 | D2: 2017 | E2: 14
A3: 1464 | B3: 42737 | C3: 0.18483162 | D3: 2017 | E3: 14
A4: 1465 | B4: 42738 | C4: 0.2532659 | D4: 2017 | E4: 14
A5: 1466 | B5: 42739 | C5: 0.27048274 | D5: 2017 | E5: 14
A6: 1467 | B6: 42740 | C6: 0.3130093 | D6: 2017 | E6: 14
A7: 1468 | B7: 42741 | C7: 0.29346017 | D7: 2017 | E7: 0
A8: 1469 | B8: 42742 | C8: 0.2132266 | D8: 2017 | E8: 0
A9: 1470 | B9: 42743 | C9: 0.24756409 | D9: 2017 | E9: 0
A10: 1471 | B10: 42744 | C10: 0.36359019 | D10: 2017 | E10: 0
A11: 1472 | B11: 42745 | C11: 0.20304725 | D11: 2017 | E11: 0
A12: 1473 | B12: 42746 | C12: 0.20133066 | D12: 2017 | E12: 0
A13: 1474 | B13: 42747 | C13: 0.28366074 | D13: 2017 | E13: 0
... A366: 1827 | B366: 43100 | C366: 0.044380142 | D366: 2017 | E366: 0

Sheet Лист16
A1: X | B1: date | D1: meanRECO | E1: year | F1: max_pulse_duration
A2: 1468 | B2: 42741 | D2: 0.29346017 | E2: 2017 | F2: 0 | I2: 0.29346017
A3: 1469 | B3: 42742 | C3: =B3-B2 -> 1 | D3: 0.2132266 | E3: 2017 | F3: 0 | I3: =D3*C3 -> 0.2132266 | J3: =I3+I2 -> 0.50668677
A4: 1470 | B4: 42743 | C4: =B4-B3 -> 1 | D4: 0.24756409 | E4: 2017 | F4: 0 | I4: =D4*C4 -> 0.24756409 | J4: =J3+I4 -> 0.75425086
A5: 1471 | B5: 42744 | C5: =B5-B4 -> 1 | D5: 0.36359019 | E5: 2017 | F5: 0 | I5: =D5*C5 -> 0.36359019 | J5: =J4+I5 -> 1.1178411
A6: 1472 | B6: 42745 | C6: =B6-B5 -> 1 | D6: 0.20304725 | E6: 2017 | F6: 0 | I6: =D6*C6 -> 0.20304725 | J6: =J5+I6 -> 1.3208883
A7: 1473 | B7: 42746 | C7: =B7-B6 -> 1 | D7: 0.20133066 | E7: 2017 | F7: 0 | I7: =D7*C7 -> 0.20133066 | J7: =J6+I7 -> 1.522219
A8: 1474 | B8: 42747 | C8: =B8-B7 -> 1 | D8: 0.28366074 | E8: 2017 | F8: 0 | I8: =D8*C8 -> 0.28366074 | J8: =J7+I8 -> 1.8058797
A9: 1475 | B9: 42748 | C9: =B9-B8 -> 1 | D9: 0.39118167 | E9: 2017 | F9: 0 | I9: =D9*C9 -> 0.39118167 | J9: =J8+I9 -> 2.1970614
A10: 1491 | B10: 42764 | C10: =B10-B9 -> 16 | D10: 0.086698576 | E10: 2017 | F10: 0 | I10: =D10*C10 -> 1.3871772 | J10: =J9+I10 -> 3.5842386
A11: 1492 | B11: 42765 | C11: =B11-B10 -> 1 | D11: 0.093822074 | E11: 2017 | F11: 0 | I11: =D11*C11 -> 0.093822074 | J11: =J10+I11 -> 3.6780607
A12: 1493 | B12: 42766 | C12: =B12-B11 -> 1 | D12: 0.10513307 | E12: 2017 | F12: 0 | I12: =D12*C12 -> 0.10513307 | J12: =J11+I12 -> 3.7831937
A13: 1494 | B13: 42767 | C13: =B13-B12 -> 1 | D13: 0.088718113 | E13: 2017 | F13: 0 | I13: =D13*C13 -> 0.088718113 | J13: =J12+I13 -> 3.8719119
A14: 1495 | B14: 42768 | C14: =B14-B13 -> 1 | D14: 0.062583671 | E14: 2017 | F14: 0 | I14: =D14*C14 -> 0.062583671 | J14: =J13+I14 -> 3.9344955
A15: 1496 | B15: 42769 | C15: =B15-B14 -> 1 | D15: 0.072757997 | E15: 2017 | F15: 0 | I15: =D15*C15 -> 0.072757997 | J15: =J14+I15 -> 4.0072535
... A266: 1827 | B266: 43100 | C266: =B266-B265 -> 1 | D266: 0.044380142 | E266: 2017 | F266: 0 | I266: =D266*C266 -> 0.044380142 | J266: =J265+I266 -> 266.47058

Sheet Лист15
A1: X | B1: date | D1: meanRECO | E1: year | F1: max_pulse_duration
A2: 1463 | B2: 42736 | D2: 0.25971469 | E2: 2017 | F2: 14 | I2: 0.25971469
A3: 1464 | B3: 42737 | C3: =B3-B2 -> 1 | D3: 0.18483162 | E3: 2017 | F3: 14 | I3: =D3*C3 -> 0.18483162 | J3: =I3+I2 -> 0.44454631
A4: 1465 | B4: 42738 | C4: =B4-B3 -> 1 | D4: 0.2532659 | E4: 2017 | F4: 14 | I4: =D4*C4 -> 0.2532659 | J4: =I4+J3 -> 0.69781222
A5: 1466 | B5: 42739 | C5: =B5-B4 -> 1 | D5: 0.27048274 | E5: 2017 | F5: 14 | I5: =D5*C5 -> 0.27048274 | J5: =I5+J4 -> 0.96829496
A6: 1467 | B6: 42740 | C6: =B6-B5 -> 1 | D6: 0.3130093 | E6: 2017 | F6: 14 | I6: =D6*C6 -> 0.3130093 | J6: =I6+J5 -> 1.2813043
A7: 1476 | B7: 42749 | C7: =B7-B6 -> 9 | D7: 0.51327315 | E7: 2017 | F7: 8 | I7: =D7*C7 -> 4.6194583 | J7: =I7+J6 -> 5.9007626
A8: 1477 | B8: 42750 | C8: =B8-B7 -> 1 | D8: 0.28675635 | E8: 2017 | F8: 8 | I8: =D8*C8 -> 0.28675635 | J8: =I8+J7 -> 6.1875189
A9: 1478 | B9: 42751 | C9: =B9-B8 -> 1 | D9: 0.41572772 | E9: 2017 | F9: 8 | I9: =D9*C9 -> 0.41572772 | J9: =I9+J8 -> 6.6032467
A10: 1479 | B10: 42752 | C10: =B10-B9 -> 1 | D10: 0.45977873 | E10: 2017 | F10: 8 | I10: =D10*C10 -> 0.45977873 | J10: =I10+J9 -> 7.0630254
A11: 1480 | B11: 42753 | C11: =B11-B10 -> 1 | D11: 0.50009495 | E11: 2017 | F11: 8 | I11: =D11*C11 -> 0.50009495 | J11: =I11+J10 -> 7.5631203
A12: 1481 | B12: 42754 | C12: =B12-B11 -> 1 | D12: 0.49654646 | E12: 2017 | F12: 8 | I12: =D12*C12 -> 0.49654646 | J12: =I12+J11 -> 8.0596668
A13: 1482 | B13: 42755 | C13: =B13-B12 -> 1 | D13: 0.57534697 | E13: 2017 | F13: 8 | I13: =D13*C13 -> 0.57534697 | J13: =I13+J12 -> 8.6350138
A14: 1483 | B14: 42756 | C14: =B14-B13 -> 1 | D14: 0.47143508 | E14: 2017 | F14: 8 | I14: =D14*C14 -> 0.47143508 | J14: =I14+J13 -> 9.1064488
A15: 1484 | B15: 42757 | C15: =B15-B14 -> 1 | D15: 0.54936163 | E15: 2017 | F15: 8 | I15: =D15*C15 -> 0.54936163 | J15: =I15+J14 -> 9.6558105
... A68: 1680 | B68: 42953 | C68: =B68-B67 -> 1 | D68: 2.2017218 | E68: 2017 | F68: 20 | I68: =D68*C68 -> 2.2017218 | J68: =I68+J67 -> 218.69825
A69: 1681 | B69: 42954 | C69: =B69-B68 -> 1 | D69: 2.3358927 | E69: 2017 | F69: 20 | I69: =D69*C69 -> 2.3358927 | J69: =I69+J68 -> 221.03415 | P69: 265
A70: 1682 | B70: 42955 | C70: =B70-B69 -> 1 | D70: 2.573778 | E70: 2017 | F70: 20 | I70: =D70*C70 -> 2.573778 | J70: =I70+J69 -> 223.60793 | P70: 370 | Q70: 635 | R70: =P70*100/Q70 -> 58.267717
A71: 1683 | B71: 42956 | C71: =B71-B70 -> 1 | D71: 2.6472574 | E71: 2017 | F71: 20 | I71: =D71*C71 -> 2.6472574 | J71: =I71+J70 -> 226.25518
A72: 1684 | B72: 42957 | C72: =B72-B71 -> 1 | D72: 2.4625296 | E72: 2017 | F72: 20 | I72: =D72*C72 -> 2.4625296 | J72: =I72+J71 -> 228.71771
A73: 1685 | B73: 42958 | C73: =B73-B72 -> 1 | D73: 2.581609 | E73: 2017 | F73: 20 | I73: =D73*C73 -> 2.581609 | J73: =I73+J72 -> 231.29932
A74: 1686 | B74: 42959 | C74: =B74-B73 -> 1 | D74: 2.5508344 | E74: 2017 | F74: 20 | I74: =D74*C74 -> 2.5508344 | J74: =I74+J73 -> 233.85016
A75: 1687 | B75: 42960 | C75: =B75-B74 -> 1 | D75: 2.3814663 | E75: 2017 | F75: 20 | I75: =D75*C75 -> 2.3814663 | J75: =I75+J74 -> 236.23162
A76: 1688 | B76: 42961 | C76: =B76-B75 -> 1 | D76: 2.4211389 | E76: 2017 | F76: 20 | I76: =D76*C76 -> 2.4211389 | J76: =I76+J75 -> 238.65276
A77: 1689 | B77: 42962 | C77: =B77-B76 -> 1 | D77: 2.5993764 | E77: 2017 | F77: 20 | I77: =D77*C77 -> 2.5993764 | J77: =I77+J76 -> 241.25214
A78: 1690 | B78: 42963 | C78: =B78-B77 -> 1 | D78: 2.7002065 | E78: 2017 | F78: 20 | I78: =D78*C78 -> 2.7002065 | J78: =I78+J77 -> 243.95234
A79: 1691 | B79: 42964 | C79: =B79-B78 -> 1 | D79: 2.9607377 | E79: 2017 | F79: 20 | I79: =D79*C79 -> 2.9607377 | J79: =I79+J78 -> 246.91308
A80: 1692 | B80: 42965 | C80: =B80-B79 -> 1 | D80: 3.1459091 | E80: 2017 | F80: 20 | I80: =D80*C80 -> 3.1459091 | J80: =I80+J79 -> 250.05899
A81: 1693 | B81: 42966 | C81: =B81-B80 -> 1 | D81: 3.0830575 | E81: 2017 | F81: 20 | I81: =D81*C81 -> 3.0830575 | J81: =I81+J80 -> 253.14205
A82: 1694 | B82: 42967 | C82: =B82-B81 -> 1 | D82: 2.9047799 | E82: 2017 | F82: 20 | I82: =D82*C82 -> 2.9047799 | J82: =I82+J81 -> 256.04683
... A101: 1820 | B101: 43093 | C101: =B101-B100 -> 1 | D101: 0.067104 | E101: 2017 | F101: 8 | I101: =D101*C101 -> 0.067104 | J101: =I101+J100 -> 368.62068

Sheet 18
A1: X | B1: date | C1: meanRECO | D1: year | E1: max_pulse_duration
A2: 1828 | B2: 43101 | C2: 0.21324254 | D2: 2018 | E2: 0
A3: 1829 | B3: 43102 | C3: 0.19695441 | D3: 2018 | E3: 0
A4: 1830 | B4: 43103 | C4: 0.21800402 | D4: 2018 | E4: 0
A5: 1831 | B5: 43104 | C5: 0.21282975 | D5: 2018 | E5: 0
A6: 1832 | B6: 43105 | C6: 0.29110473 | D6: 2018 | E6: 0
A7: 1833 | B7: 43106 | C7: 0.37537006 | D7: 2018 | E7: 0
A8: 1834 | B8: 43107 | C8: 0.41385838 | D8: 2018 | E8: 0
A9: 1835 | B9: 43108 | C9: 0.51654698 | D9: 2018 | E9: 0
A10: 1836 | B10: 43109 | C10: 0.6146141 | D10: 2018 | E10: 0
A11: 1837 | B11: 43110 | C11: 0.54988418 | D11: 2018 | E11: 0
A12: 1838 | B12: 43111 | C12: 0.40699998 | D12: 2018 | E12: 0
A13: 1839 | B13: 43112 | C13: 0.42032446 | D13: 2018 | E13: 0
... A366: 2192 | B366: 43465 | C366: 0.10949835 | D366: 2018 | E366: 8

Sheet Лист14
A1: X | B1: date | D1: meanRECO | E1: year | F1: max_pulse_duration
A2: 1828 | B2: 43101 | D2: 0.21324254 | E2: 2018 | F2: 0 | I2: 0.21324254
A3: 1829 | B3: 43102 | C3: =B3-B2 -> 1 | D3: 0.19695441 | E3: 2018 | F3: 0 | I3: =D3*C3 -> 0.19695441 | J3: =I3+I2 -> 0.41019695
A4: 1830 | B4: 43103 | C4: =B4-B3 -> 1 | D4: 0.21800402 | E4: 2018 | F4: 0 | I4: =D4*C4 -> 0.21800402 | J4: =J3+I4 -> 0.62820097
A5: 1831 | B5: 43104 | C5: =B5-B4 -> 1 | D5: 0.21282975 | E5: 2018 | F5: 0 | I5: =D5*C5 -> 0.21282975 | J5: =J4+I5 -> 0.84103072
A6: 1832 | B6: 43105 | C6: =B6-B5 -> 1 | D6: 0.29110473 | E6: 2018 | F6: 0 | I6: =D6*C6 -> 0.29110473 | J6: =J5+I6 -> 1.1321354
A7: 1833 | B7: 43106 | C7: =B7-B6 -> 1 | D7: 0.37537006 | E7: 2018 | F7: 0 | I7: =D7*C7 -> 0.37537006 | J7: =J6+I7 -> 1.5075055
A8: 1834 | B8: 43107 | C8: =B8-B7 -> 1 | D8: 0.41385838 | E8: 2018 | F8: 0 | I8: =D8*C8 -> 0.41385838 | J8: =J7+I8 -> 1.9213639
A9: 1835 | B9: 43108 | C9: =B9-B8 -> 1 | D9: 0.51654698 | E9: 2018 | F9: 0 | I9: =D9*C9 -> 0.51654698 | J9: =J8+I9 -> 2.4379109
A10: 1836 | B10: 43109 | C10: =B10-B9 -> 1 | D10: 0.6146141 | E10: 2018 | F10: 0 | I10: =D10*C10 -> 0.6146141 | J10: =J9+I10 -> 3.052525
A11: 1837 | B11: 43110 | C11: =B11-B10 -> 1 | D11: 0.54988418 | E11: 2018 | F11: 0 | I11: =D11*C11 -> 0.54988418 | J11: =J10+I11 -> 3.6024091
A12: 1838 | B12: 43111 | C12: =B12-B11 -> 1 | D12: 0.40699998 | E12: 2018 | F12: 0 | I12: =D12*C12 -> 0.40699998 | J12: =J11+I12 -> 4.0094091
A13: 1839 | B13: 43112 | C13: =B13-B12 -> 1 | D13: 0.42032446 | E13: 2018 | F13: 0 | I13: =D13*C13 -> 0.42032446 | J13: =J12+I13 -> 4.4297336
A14: 1840 | B14: 43113 | C14: =B14-B13 -> 1 | D14: 0.27304346 | E14: 2018 | F14: 0 | I14: =D14*C14 -> 0.27304346 | J14: =J13+I14 -> 4.702777
A15: 1841 | B15: 43114 | C15: =B15-B14 -> 1 | D15: 0.15018493 | E15: 2018 | F15: 0 | I15: =D15*C15 -> 0.15018493 | J15: =J14+I15 -> 4.852962
... A197: 2188 | B197: 43461 | C197: =B197-B196 -> 1 | D197: 0.14174781 | E197: 2018 | F197: 0 | I197: =D197*C197 -> 0.14174781 | J197: =J196+I197 -> 262.6224

Sheet Лист13
A1: X | B1: date | D1: meanRECO | E1: year | F1: max_pulse_duration
A2: 1874 | B2: 43147 | D2: 0.43808861 | E2: 2018 | F2: 14 | I2: 0.43808861
A3: 1875 | B3: 43148 | C3: =B3-B2 -> 1 | D3: 0.65195144 | E3: 2018 | F3: 14 | I3: =D3*C3 -> 0.65195144 | J3: =I3+I2 -> 1.09004
A4: 1876 | B4: 43149 | C4: =B4-B3 -> 1 | D4: 0.6178898 | E4: 2018 | F4: 14 | I4: =D4*C4 -> 0.6178898 | J4: =J3+I4 -> 1.7079298
A5: 1877 | B5: 43150 | C5: =B5-B4 -> 1 | D5: 0.71292119 | E5: 2018 | F5: 14 | I5: =D5*C5 -> 0.71292119 | J5: =J4+I5 -> 2.420851
A6: 1878 | B6: 43151 | C6: =B6-B5 -> 1 | D6: 0.42546933 | E6: 2018 | F6: 14 | I6: =D6*C6 -> 0.42546933 | J6: =J5+I6 -> 2.8463204
A7: 1879 | B7: 43152 | C7: =B7-B6 -> 1 | D7: 0.47608519 | E7: 2018 | F7: 14 | I7: =D7*C7 -> 0.47608519 | J7: =J6+I7 -> 3.3224056
A8: 1880 | B8: 43153 | C8: =B8-B7 -> 1 | D8: 0.3671482 | E8: 2018 | F8: 14 | I8: =D8*C8 -> 0.3671482 | J8: =J7+I8 -> 3.6895538
A9: 1881 | B9: 43154 | C9: =B9-B8 -> 1 | D9: 0.40475521 | E9: 2018 | F9: 14 | I9: =D9*C9 -> 0.40475521 | J9: =J8+I9 -> 4.094309
A10: 1882 | B10: 43155 | C10: =B10-B9 -> 1 | D10: 0.24728635 | E10: 2018 | F10: 14 | I10: =D10*C10 -> 0.24728635 | J10: =J9+I10 -> 4.3415953
A11: 1883 | B11: 43156 | C11: =B11-B10 -> 1 | D11: 0.28880559 | E11: 2018 | F11: 14 | I11: =D11*C11 -> 0.28880559 | J11: =J10+I11 -> 4.6304009
A12: 1884 | B12: 43157 | C12: =B12-B11 -> 1 | D12: 0.34622641 | E12: 2018 | F12: 14 | I12: =D12*C12 -> 0.34622641 | J12: =J11+I12 -> 4.9766273
A13: 1885 | B13: 43158 | C13: =B13-B12 -> 1 | D13: 0.3178364 | E13: 2018 | F13: 14 | I13: =D13*C13 -> 0.3178364 | J13: =J12+I13 -> 5.2944637
A14: 1886 | B14: 43159 | C14: =B14-B13 -> 1 | D14: 0.16842441 | E14: 2018 | F14: 14 | I14: =D14*C14 -> 0.16842441 | J14: =J13+I14 -> 5.4628881
A15: 1887 | B15: 43160 | C15: =B15-B14 -> 1 | D15: 0.37298734 | E15: 2018 | F15: 14 | I15: =D15*C15 -> 0.37298734 | J15: =J14+I15 -> 5.8358755
... A140: 2138 | B140: 43411 | C140: =B140-B139 -> 1 | D140: 0.74541291 | E140: 2018 | F140: 20 | I140: =D140*C140 -> 0.74541291 | J140: =J139+I140 -> 302.56368
A141: 2139 | B141: 43412 | C141: =B141-B140 -> 1 | D141: 0.77158608 | E141: 2018 | F141: 20 | I141: =D141*C141 -> 0.77158608 | J141: =J140+I141 -> 303.33526 | Q141: 320 | S141: =Q141*100/R142 -> 55.172414
A142: 2140 | B142: 43413 | C142: =B142-B141 -> 1 | D142: 0.88088153 | E142: 2018 | F142: 20 | I142: =D142*C142 -> 0.88088153 | J142: =J141+I142 -> 304.21614 | Q142: 260 | R142: 580
A143: 2141 | B143: 43414 | C143: =B143-B142 -> 1 | D143: 0.73732344 | E143: 2018 | F143: 20 | I143: =D143*C143 -> 0.73732344 | J143: =J142+I143 -> 304.95347
A144: 2142 | B144: 43415 | C144: =B144-B143 -> 1 | D144: 0.68046588 | E144: 2018 | F144: 20 | I144: =D144*C144 -> 0.68046588 | J144: =J143+I144 -> 305.63393
A145: 2161 | B145: 43434 | C145: =B145-B144 -> 19 | D145: 0.28462265 | E145: 2018 | F145: 8 | I145: =D145*C145 -> 5.4078304 | J145: =J144+I145 -> 311.04176
A146: 2162 | B146: 43435 | C146: =B146-B145 -> 1 | D146: 0.22462475 | E146: 2018 | F146: 8 | I146: =D146*C146 -> 0.22462475 | J146: =J145+I146 -> 311.26639
A147: 2163 | B147: 43436 | C147: =B147-B146 -> 1 | D147: 0.23307883 | E147: 2018 | F147: 8 | I147: =D147*C147 -> 0.23307883 | J147: =J146+I147 -> 311.49947
A148: 2164 | B148: 43437 | C148: =B148-B147 -> 1 | D148: 0.23708449 | E148: 2018 | F148: 8 | I148: =D148*C148 -> 0.23708449 | J148: =J147+I148 -> 311.73655
A149: 2165 | B149: 43438 | C149: =B149-B148 -> 1 | D149: 0.32441139 | E149: 2018 | F149: 8 | I149: =D149*C149 -> 0.32441139 | J149: =J148+I149 -> 312.06096
A150: 2166 | B150: 43439 | C150: =B150-B149 -> 1 | D150: 0.3523378 | E150: 2018 | F150: 8 | I150: =D150*C150 -> 0.3523378 | J150: =J149+I150 -> 312.4133
A151: 2167 | B151: 43440 | C151: =B151-B150 -> 1 | D151: 0.36118494 | E151: 2018 | F151: 8 | I151: =D151*C151 -> 0.36118494 | J151: =J150+I151 -> 312.77448
A152: 2168 | B152: 43441 | C152: =B152-B151 -> 1 | D152: 0.25596784 | E152: 2018 | F152: 8 | I152: =D152*C152 -> 0.25596784 | J152: =J151+I152 -> 313.03045
A153: 2169 | B153: 43442 | C153: =B153-B152 -> 1 | D153: 0.30667777 | E153: 2018 | F153: 14 | I153: =D153*C153 -> 0.30667777 | J153: =J152+I153 -> 313.33713
A154: 2170 | B154: 43443 | C154: =B154-B153 -> 1 | D154: 0.39425871 | E154: 2018 | F154: 14 | I154: =D154*C154 -> 0.39425871 | J154: =J153+I154 -> 313.73139
... A170: 2192 | B170: 43465 | C170: =B170-B169 -> 1 | D170: 0.10949835 | E170: 2018 | F170: 8 | I170: =D170*C170 -> 0.10949835 | J170: =J169+I170 -> 318.50816

Sheet 19
A1: X | B1: date | C1: meanRECO | D1: year | E1: max_pulse_duration
A2: 2193 | B2: 43466 | C2: 0.3053392 | D2: 2019 | E2: 8
A3: 2194 | B3: 43467 | C3: 0.24346281 | D3: 2019 | E3: 8
A4: 2195 | B4: 43468 | C4: 0.46039524 | D4: 2019 | E4: 8
A5: 2196 | B5: 43469 | C5: 0.46295522 | D5: 2019 | E5: 8
A6: 2197 | B6: 43470 | C6: 0.5071465 | D6: 2019 | E6: 0
A7: 2198 | B7: 43471 | C7: 0.53650933 | D7: 2019 | E7: 8
A8: 2199 | B8: 43472 | C8: 0.49369915 | D8: 2019 | E8: 8
A9: 2200 | B9: 43473 | C9: 0.54459772 | D9: 2019 | E9: 8
A10: 2201 | B10: 43474 | C10: 0.5773698 | D10: 2019 | E10: 8
A11: 2202 | B11: 43475 | C11: 0.48096865 | D11: 2019 | E11: 8
A12: 2203 | B12: 43476 | C12: 0.46281887 | D12: 2019 | E12: 8
A13: 2204 | B13: 43477 | C13: 0.41506545 | D13: 2019 | E13: 8
... A351: 2557 | B351: 43830 | C351: 0.43441448 | D351: 2019 | E351: 8

Sheet Лист12
A1: X | B1: date | D1: meanRECO | E1: year | F1: max_pulse_duration
A2: 2197 | B2: 43470 | D2: 0.5071465 | E2: 2019 | F2: 0 | H2: 0.5071465
A3: 2206 | B3: 43479 | C3: =B3-B2 -> 9 | D3: 0.3677723 | E3: 2019 | F3: 0 | H3: =D3*C3 -> 3.3099507 | I3: =H3+H2 -> 3.8170972
A4: 2207 | B4: 43480 | C4: =B4-B3 -> 1 | D4: 0.36349006 | E4: 2019 | F4: 0 | H4: =D4*C4 -> 0.36349006 | I4: =H4+I3 -> 4.1805873
A5: 2208 | B5: 43481 | C5: =B5-B4 -> 1 | D5: 0.35338354 | E5: 2019 | F5: 0 | H5: =D5*C5 -> 0.35338354 | I5: =H5+I4 -> 4.5339708
A6: 2209 | B6: 43482 | C6: =B6-B5 -> 1 | D6: 0.36241184 | E6: 2019 | F6: 0 | H6: =D6*C6 -> 0.36241184 | I6: =H6+I5 -> 4.8963827
A7: 2210 | B7: 43483 | C7: =B7-B6 -> 1 | D7: 0.30705732 | E7: 2019 | F7: 0 | H7: =D7*C7 -> 0.30705732 | I7: =H7+I6 -> 5.20344
A8: 2211 | B8: 43484 | C8: =B8-B7 -> 1 | D8: 0.28770604 | E8: 2019 | F8: 0 | H8: =D8*C8 -> 0.28770604 | I8: =H8+I7 -> 5.491146
A9: 2212 | B9: 43485 | C9: =B9-B8 -> 1 | D9: 0.34733165 | E9: 2019 | F9: 0 | H9: =D9*C9 -> 0.34733165 | I9: =H9+I8 -> 5.8384777
A10: 2213 | B10: 43486 | C10: =B10-B9 -> 1 | D10: 0.36868405 | E10: 2019 | F10: 0 | H10: =D10*C10 -> 0.36868405 | I10: =H10+I9 -> 6.2071617
A11: 2214 | B11: 43487 | C11: =B11-B10 -> 1 | D11: 0.24864415 | E11: 2019 | F11: 0 | H11: =D11*C11 -> 0.24864415 | I11: =H11+I10 -> 6.4558059
A12: 2215 | B12: 43488 | C12: =B12-B11 -> 1 | D12: 0.29029572 | E12: 2019 | F12: 0 | H12: =D12*C12 -> 0.29029572 | I12: =H12+I11 -> 6.7461016
A13: 2216 | B13: 43489 | C13: =B13-B12 -> 1 | D13: 0.30629034 | E13: 2019 | F13: 0 | H13: =D13*C13 -> 0.30629034 | I13: =H13+I12 -> 7.0523919
A14: 2217 | B14: 43490 | C14: =B14-B13 -> 1 | D14: 0.33214357 | E14: 2019 | F14: 0 | H14: =D14*C14 -> 0.33214357 | I14: =H14+I13 -> 7.3845355
A15: 2218 | B15: 43491 | C15: =B15-B14 -> 1 | D15: 0.34922215 | E15: 2019 | F15: 0 | H15: =D15*C15 -> 0.34922215 | I15: =H15+I14 -> 7.7337576
... A168: 2515 | B168: 43788 | C168: =B168-B167 -> 1 | D168: 0.87721168 | E168: 2019 | F168: 0 | H168: =D168*C168 -> 0.87721168 | I168: =H168+I167 -> 259.23266

Sheet Лист11
A1: X | B1: date | D1: meanRECO | E1: year | F1: max_pulse_duration
A2: 2193 | B2: 43466 | D2: 0.3053392 | E2: 2019 | F2: 8 | H2: 0.3053392
A3: 2194 | B3: 43467 | C3: =B3-B2 -> 1 | D3: 0.24346281 | E3: 2019 | F3: 8 | H3: =C3*D3 -> 0.24346281 | I3: =H3+H2 -> 0.54880202
A4: 2195 | B4: 43468 | C4: =B4-B3 -> 1 | D4: 0.46039524 | E4: 2019 | F4: 8 | H4: =C4*D4 -> 0.46039524 | I4: =H4+I3 -> 1.0091973
A5: 2196 | B5: 43469 | C5: =B5-B4 -> 1 | D5: 0.46295522 | E5: 2019 | F5: 8 | H5: =C5*D5 -> 0.46295522 | I5: =H5+I4 -> 1.4721525
A6: 2198 | B6: 43471 | C6: =B6-B5 -> 2 | D6: 0.53650933 | E6: 2019 | F6: 8 | H6: =C6*D6 -> 1.0730187 | I6: =H6+I5 -> 2.5451711
A7: 2199 | B7: 43472 | C7: =B7-B6 -> 1 | D7: 0.49369915 | E7: 2019 | F7: 8 | H7: =C7*D7 -> 0.49369915 | I7: =H7+I6 -> 3.0388703
A8: 2200 | B8: 43473 | C8: =B8-B7 -> 1 | D8: 0.54459772 | E8: 2019 | F8: 8 | H8: =C8*D8 -> 0.54459772 | I8: =H8+I7 -> 3.583468
A9: 2201 | B9: 43474 | C9: =B9-B8 -> 1 | D9: 0.5773698 | E9: 2019 | F9: 8 | H9: =C9*D9 -> 0.5773698 | I9: =H9+I8 -> 4.1608378
A10: 2202 | B10: 43475 | C10: =B10-B9 -> 1 | D10: 0.48096865 | E10: 2019 | F10: 8 | H10: =C10*D10 -> 0.48096865 | I10: =H10+I9 -> 4.6418065
A11: 2203 | B11: 43476 | C11: =B11-B10 -> 1 | D11: 0.46281887 | E11: 2019 | F11: 8 | H11: =C11*D11 -> 0.46281887 | I11: =H11+I10 -> 5.1046253
A12: 2204 | B12: 43477 | C12: =B12-B11 -> 1 | D12: 0.41506545 | E12: 2019 | F12: 8 | H12: =C12*D12 -> 0.41506545 | I12: =H12+I11 -> 5.5196908
A13: 2205 | B13: 43478 | C13: =B13-B12 -> 1 | D13: 0.39743949 | E13: 2019 | F13: 8 | H13: =C13*D13 -> 0.39743949 | I13: =H13+I12 -> 5.9171303
A14: 2233 | B14: 43506 | C14: =B14-B13 -> 28 | D14: 0.24776488 | E14: 2019 | F14: 8 | H14: =C14*D14 -> 6.9374167 | I14: =H14+I13 -> 12.854547
A15: 2234 | B15: 43507 | C15: =B15-B14 -> 1 | D15: 0.25151119 | E15: 2019 | F15: 8 | H15: =C15*D15 -> 0.25151119 | I15: =H15+I14 -> 13.106058
... A165: 2538 | B165: 43811 | C165: =B165-B164 -> 1 | D165: 0.72340545 | E165: 2019 | F165: 20 | H165: =C165*D165 -> 0.72340545 | I165: =H165+I164 -> 386.66155
A166: 2539 | B166: 43812 | C166: =B166-B165 -> 1 | D166: 0.68594143 | E166: 2019 | F166: 20 | H166: =C166*D166 -> 0.68594143 | I166: =H166+I165 -> 387.34749 | P166: 395 | R166: =369*100/655 -> 56.335878
A167: 2540 | B167: 43813 | C167: =B167-B166 -> 1 | D167: 0.51705945 | E167: 2019 | F167: 20 | H167: =C167*D167 -> 0.51705945 | I167: =H167+I166 -> 387.86455 | P167: 260 | Q167: 655
A168: 2541 | B168: 43814 | C168: =B168-B167 -> 1 | D168: 0.47590803 | E168: 2019 | F168: 20 | H168: =C168*D168 -> 0.47590803 | I168: =H168+I167 -> 388.34046
A169: 2542 | B169: 43815 | C169: =B169-B168 -> 1 | D169: 0.33316041 | E169: 2019 | F169: 20 | H169: =C169*D169 -> 0.33316041 | I169: =H169+I168 -> 388.67362
A170: 2543 | B170: 43816 | C170: =B170-B169 -> 1 | D170: 0.6368792 | E170: 2019 | F170: 20 | H170: =C170*D170 -> 0.6368792 | I170: =H170+I169 -> 389.3105
A171: 2544 | B171: 43817 | C171: =B171-B170 -> 1 | D171: 0.90627214 | E171: 2019 | F171: 20 | H171: =C171*D171 -> 0.90627214 | I171: =H171+I170 -> 390.21677
A172: 2545 | B172: 43818 | C172: =B172-B171 -> 1 | D172: 0.6220702 | E172: 2019 | F172: 20 | H172: =C172*D172 -> 0.6220702 | I172: =H172+I171 -> 390.83884
A173: 2546 | B173: 43819 | C173: =B173-B172 -> 1 | D173: 0.51787228 | E173: 2019 | F173: 20 | H173: =C173*D173 -> 0.51787228 | I173: =H173+I172 -> 391.35671
A174: 2547 | B174: 43820 | C174: =B174-B173 -> 1 | D174: 0.38603315 | E174: 2019 | F174: 20 | H174: =C174*D174 -> 0.38603315 | I174: =H174+I173 -> 391.74274
A175: 2548 | B175: 43821 | C175: =B175-B174 -> 1 | D175: 0.38392752 | E175: 2019 | F175: 20 | H175: =C175*D175 -> 0.38392752 | I175: =H175+I174 -> 392.12667
A176: 2549 | B176: 43822 | C176: =B176-B175 -> 1 | D176: 0.31441853 | E176: 2019 | F176: 20 | H176: =C176*D176 -> 0.31441853 | I176: =H176+I175 -> 392.44109
A177: 2550 | B177: 43823 | C177: =B177-B176 -> 1 | D177: 0.31568477 | E177: 2019 | F177: 20 | H177: =C177*D177 -> 0.31568477 | I177: =H177+I176 -> 392.75677
A178: 2551 | B178: 43824 | C178: =B178-B177 -> 1 | D178: 0.26773379 | E178: 2019 | F178: 20 | H178: =C178*D178 -> 0.26773379 | I178: =H178+I177 -> 393.02451
A179: 2552 | B179: 43825 | C179: =B179-B178 -> 1 | D179: 0.42504911 | E179: 2019 | F179: 20 | H179: =C179*D179 -> 0.42504911 | I179: =H179+I178 -> 393.44956
... A184: 2557 | B184: 43830 | C184: =B184-B183 -> 1 | D184: 0.43441448 | E184: 2019 | F184: 8 | H184: =C184*D184 -> 0.43441448 | I184: =H184+I183 -> 395.10431

Sheet 20
A1: X | B1: date | D1: meanRECO | E1: year | F1: max_pulse_duration | I1: CumNP | J1: CumP
A2: 2558 | B2: 43831 | D2: 0.51665842 | E2: 2020 | F2: 8
A3: 2559 | B3: 43832 | D3: 0.5580343 | E3: 2020 | F3: 8
A4: 2560 | B4: 43833 | D4: 0.44303299 | E4: 2020 | F4: 8
A5: 2561 | B5: 43834 | D5: 0.52062513 | E5: 2020 | F5: 0
A6: 2562 | B6: 43835 | C6: =B6-B5 -> 1 | D6: 0.39775233 | E6: 2020 | F6: 0 | I6: =Лист9!C3+Лист9!C2 -> 0.91837746
A7: 2563 | B7: 43836 | C7: =B7-B6 -> 1 | D7: 0.18707037 | E7: 2020 | F7: 0 | I7: =Лист9!C4+I6 -> 1.1054478
A8: 2564 | B8: 43837 | C8: =B8-B7 -> 1 | D8: 0.16595294 | E8: 2020 | F8: 0 | I8: =Лист9!C5+I7 -> 1.2714008
A9: 2565 | B9: 43838 | C9: =B9-B8 -> 1 | D9: 0.19132664 | E9: 2020 | F9: 0 | I9: =Лист9!C6+I8 -> 1.4627274
A10: 2566 | B10: 43839 | C10: =B10-B9 -> 1 | D10: 0.19563804 | E10: 2020 | F10: 0 | I10: =Лист9!C7+I9 -> 1.6583655
A11: 2567 | B11: 43840 | C11: =B11-B10 -> 1 | D11: 0.12547643 | E11: 2020 | F11: 0 | I11: =Лист9!C8+I10 -> 1.7838419
A12: 2568 | B12: 43841 | C12: =B12-B11 -> 1 | D12: 0.17753533 | E12: 2020 | F12: 0 | I12: =Лист9!C9+I11 -> 1.9613772
A13: 2569 | B13: 43842 | C13: =B13-B12 -> 1 | D13: 0.17347564 | E13: 2020 | F13: 0 | I13: =Лист9!C10+I12 -> 2.1348529
A14: 2570 | B14: 43843 | C14: =B14-B13 -> 1 | D14: 0.22957459 | E14: 2020 | F14: 0 | I14: =Лист9!C11+I13 -> 2.3644274
A15: 2571 | B15: 43844 | C15: =B15-B14 -> 1 | D15: 0.26465874 | E15: 2020 | F15: 0 | I15: =Лист9!C12+I14 -> 2.6290862
A16: 2572 | B16: 43845 | C16: =B16-B15 -> 1 | D16: 0.29374338 | E16: 2020 | F16: 0 | I16: =Лист9!C13+I15 -> 2.9228296
A17: 2573 | B17: 43846 | C17: =B17-B16 -> 1 | D17: 0.35474285 | E17: 2020 | F17: 0 | I17: =Лист9!C14+I16 -> 3.2775724
A18: 2574 | B18: 43847 | C18: =B18-B17 -> 1 | D18: 0.29273308 | E18: 2020 | F18: 0 | I18: =Лист9!C15+I17 -> 3.5703055
... A63: 2619 | B63: 43892 | C63: =B63-B62 -> 1 | D63: 0.74532123 | E63: 2020 | F63: 0 | I63: =Лист9!C60+I62 -> 23.603711
A64: 2620 | B64: 43893 | D64: 0.49490032 | E64: 2020 | F64: 8
A65: 2621 | B65: 43894 | D65: 0.66575077 | E65: 2020 | F65: 8
A66: 2622 | B66: 43895 | D66: 1.120254 | E66: 2020 | F66: 8
A67: 2623 | B67: 43896 | D67: 0.9601764 | E67: 2020 | F67: 8
A68: 2624 | B68: 43897 | D68: 0.81268519 | E68: 2020 | F68: 8
A69: 2625 | B69: 43898 | D69: 0.48672088 | E69: 2020 | F69: 8
A70: 2626 | B70: 43899 | D70: 0.51459229 | E70: 2020 | F70: 14
A71: 2627 | B71: 43900 | D71: 0.55528255 | E71: 2020 | F71: 14
A72: 2628 | B72: 43901 | D72: 0.65116451 | E72: 2020 | F72: 14
A73: 2629 | B73: 43902 | D73: 0.63473092 | E73: 2020 | F73: 14
A74: 2630 | B74: 43903 | D74: 0.56837444 | E74: 2020 | F74: 14
A75: 2631 | B75: 43904 | D75: 0.57257939 | E75: 2020 | F75: 14
... A93: 2649 | B93: 43922 | D93: 0.90886835 | E93: 2020 | F93: 14
A94: 2650 | B94: 43923 | C94: =B94-B63 -> 31 | D94: 0.89634416 | E94: 2020 | F94: 0 | I94: =Лист9!C61+I93 -> 27.786669
A95: 2651 | B95: 43924 | C95: =B95-B94 -> 1 | D95: 0.93987183 | E95: 2020 | F95: 0 | I95: =Лист9!C62+I94 -> 28.726541
A96: 2652 | B96: 43925 | C96: =B96-B95 -> 1 | D96: 0.95303697 | E96: 2020 | F96: 0 | I96: =Лист9!C63+I95 -> 29.679578
A97: 2653 | B97: 43926 | C97: =B97-B96 -> 1 | D97: 0.97380361 | E97: 2020 | F97: 0 | I97: =Лист9!C64+I96 -> 30.653381
A98: 2654 | B98: 43927 | C98: =B98-B97 -> 1 | D98: 0.9320152 | E98: 2020 | F98: 0 | I98: =Лист9!C65+I97 -> 31.585397
A99: 2655 | B99: 43928 | C99: =B99-B98 -> 1 | D99: 0.86316057 | E99: 2020 | F99: 0 | I99: =Лист9!C66+I98 -> 32.448557
A100: 2656 | B100: 43929 | C100: =B100-B99 -> 1 | D100: 0.91817104 | E100: 2020 | F100: 0 | I100: =Лист9!C67+I99 -> 33.366728
A101: 2657 | B101: 43930 | C101: =B101-B100 -> 1 | D101: 0.78403108 | E101: 2020 | F101: 0 | I101: =Лист9!C68+I100 -> 34.150759
...

Sheet Лист9
C2: ='20'!D5 -> 0.52062513
C3: ='20'!D6*'20'!C6 -> 0.39775233 | D3: =C3+C2 -> 0.91837746
C4: ='20'!D7*'20'!C7 -> 0.18707037 | D4: =C4+D3 -> 1.1054478
C5: ='20'!D8*'20'!C8 -> 0.16595294 | D5: =C5+D4 -> 1.2714008
C6: ='20'!D9*'20'!C9 -> 0.19132664 | D6: =C6+D5 -> 1.4627274
C7: ='20'!D10*'20'!C10 -> 0.19563804 | D7: =C7+D6 -> 1.6583655
C8: ='20'!D11*'20'!C11 -> 0.12547643 | D8: =C8+D7 -> 1.7838419
C9: ='20'!D12*'20'!C12 -> 0.17753533 | D9: =C9+D8 -> 1.9613772
C10: ='20'!D13*'20'!C13 -> 0.17347564 | D10: =C10+D9 -> 2.1348529
C11: ='20'!D14*'20'!C14 -> 0.22957459 | D11: =C11+D10 -> 2.3644274
C12: ='20'!D15*'20'!C15 -> 0.26465874 | D12: =C12+D11 -> 2.6290862
C13: ='20'!D16*'20'!C16 -> 0.29374338 | D13: =C13+D12 -> 2.9228296
C14: ='20'!D17*'20'!C17 -> 0.35474285 | D14: =C14+D13 -> 3.2775724
C15: ='20'!D18*'20'!C18 -> 0.29273308 | D15: =C15+D14 -> 3.5703055
... C60: ='20'!D63*'20'!C63 -> 0.74532123 | D60: =C60+D59 -> 23.603711
C61: ='20'!D94*'20'!C94 -> 27.786669 | D61: =C61+D60 -> 51.39038
C62: ='20'!D95*'20'!C95 -> 0.93987183 | D62: =C62+D61 -> 52.330252
C63: ='20'!D96*'20'!C96 -> 0.95303697 | D63: =C63+D62 -> 53.283289
C64: ='20'!D97*'20'!C97 -> 0.97380361 | D64: =C64+D63 -> 54.257092
C65: ='20'!D98*'20'!C98 -> 0.9320152 | D65: =C65+D64 -> 55.189107
C66: ='20'!D99*'20'!C99 -> 0.86316057 | D66: =C66+D65 -> 56.052268
C67: ='20'!D100*'20'!C100 -> 0.91817104 | D67: =C67+D66 -> 56.970439
C68: ='20'!D101*'20'!C101 -> 0.78403108 | D68: =C68+D67 -> 57.75447
C69: ='20'!D102*'20'!C102 -> 0.85743504 | D69: =C69+D68 -> 58.611905
C70: ='20'!D111*'20'!C111 -> 8.9380692 | D70: =C70+D69 -> 67.549974
C71: ='20'!D112*'20'!C112 -> 1.0917097 | D71: =C71+D70 -> 68.641684
C72: ='20'!D113*'20'!C113 -> 1.0803745 | D72: =C72+D71 -> 69.722059
C73: ='20'!D114*'20'!C114 -> 0.91153245 | D73: =C73+D72 -> 70.633591
C74: ='20'!D115*'20'!C115 -> 1.0948534 | D74: =C74+D73 -> 71.728444
C75: ='20'!D116*'20'!C116 -> 1.1329643 | D75: =C75+D74 -> 72.861409
C76: ='20'!D117*'20'!C117 -> 1.1693362 | D76: =C76+D75 -> 74.030745
C77: ='20'!D118*'20'!C118 -> 1.188541 | D77: =C77+D76 -> 75.219286
C78: ='20'!D119*'20'!C119 -> 1.1063635 | D78: =C78+D77 -> 76.325649
C79: ='20'!D120*'20'!C120 -> 1.0026273 | D79: =C79+D78 -> 77.328277
C80: ='20'!D121*'20'!C121 -> 1.131748 | D80: =C80+D79 -> 78.460025
C81: ='20'!D122*'20'!C122 -> 1.1198579 | D81: =C81+D80 -> 79.579883
... C143: ='20'!D184*'20'!C184 -> 0.92507518 | D143: =C143+D142 -> 137.07113
C144: ='20'!D199*'20'!C199 -> 16.357032 | D144: =C144+D143 -> 153.42817
C145: ='20'!D200*'20'!C200 -> 0.99598462 | D145: =C145+D144 -> 154.42415
C146: ='20'!D201*'20'!C201 -> 1.0339884 | D146: =C146+D145 -> 155.45814
...

Sheet Лист10
A1: X | B1: date | D1: meanRECO
A2: 2558 | B2: 43831 | D2: 0.51665842 | E2: 0.51665842
A3: 2559 | B3: 43832 | C3: =B3-B2 -> 1 | D3: 0.5580343 | E3: =D3*C3 -> 0.5580343 | F3: =E3+E2 -> 1.0746927
A4: 2560 | B4: 43833 | C4: =B4-B3 -> 1 | D4: 0.44303299 | E4: =D4*C4 -> 0.44303299 | F4: =E4+F3 -> 1.5177257
A5: 2620 | B5: 43893 | C5: =B5-B4 -> 60 | D5: 0.49490032 | E5: =D5*C5 -> 29.694019 | F5: =E5+F4 -> 31.211745
A6: 2621 | B6: 43894 | C6: =B6-B5 -> 1 | D6: 0.66575077 | E6: =D6*C6 -> 0.66575077 | F6: =E6+F5 -> 31.877496
A7: 2622 | B7: 43895 | C7: =B7-B6 -> 1 | D7: 1.120254 | E7: =D7*C7 -> 1.120254 | F7: =E7+F6 -> 32.99775
A8: 2623 | B8: 43896 | C8: =B8-B7 -> 1 | D8: 0.9601764 | E8: =D8*C8 -> 0.9601764 | F8: =E8+F7 -> 33.957926
A9: 2624 | B9: 43897 | C9: =B9-B8 -> 1 | D9: 0.81268519 | E9: =D9*C9 -> 0.81268519 | F9: =E9+F8 -> 34.770611
A10: 2625 | B10: 43898 | C10: =B10-B9 -> 1 | D10: 0.48672088 | E10: =D10*C10 -> 0.48672088 | F10: =E10+F9 -> 35.257332
A11: 2626 | B11: 43899 | C11: =B11-B10 -> 1 | D11: 0.51459229 | E11: =D11*C11 -> 0.51459229 | F11: =E11+F10 -> 35.771924
A12: 2627 | B12: 43900 | C12: =B12-B11 -> 1 | D12: 0.55528255 | E12: =D12*C12 -> 0.55528255 | F12: =E12+F11 -> 36.327207
A13: 2628 | B13: 43901 | C13: =B13-B12 -> 1 | D13: 0.65116451 | E13: =D13*C13 -> 0.65116451 | F13: =E13+F12 -> 36.978371
A14: 2629 | B14: 43902 | C14: =B14-B13 -> 1 | D14: 0.63473092 | E14: =D14*C14 -> 0.63473092 | F14: =E14+F13 -> 37.613102
A15: 2630 | B15: 43903 | C15: =B15-B14 -> 1 | D15: 0.56837444 | E15: =D15*C15 -> 0.56837444 | F15: =E15+F14 -> 38.181477
... A95: 2905 | B95: 44178 | C95: =B95-B94 -> 1 | D95: 0.33613886 | E95: =D95*C95 -> 0.33613886 | F95: =E95+F94 -> 287.37353
A96: 2906 | B96: 44179 | C96: =B96-B95 -> 1 | D96: 0.25681295 | E96: =D96*C96 -> 0.25681295 | F96: =E96+F95 -> 287.63035 | J96: 240
A97: 2907 | B97: 44180 | C97: =B97-B96 -> 1 | D97: 0.12661441 | E97: =D97*C97 -> 0.12661441 | F97: =E97+F96 -> 287.75696 | J97: 290 | K97: 530 | L97: =J97*100/K97 -> 54.716981
A98: 2908 | B98: 44181 | C98: =B98-B97 -> 1 | D98: 0.18544608 | E98: =D98*C98 -> 0.18544608 | F98: =E98+F97 -> 287.94241
A99: 2909 | B99: 44182 | C99: =B99-B98 -> 1 | D99: 0.31013916 | E99: =D99*C99 -> 0.31013916 | F99: =E99+F98 -> 288.25255
